//
//  URLSession+ExtensionTets.swift
//  ResultPromisesTests
//
//  Created by Mykhailo Vorontsov on 9/14/17.
//  Copyright Â© 2017 Mykhailo Vorontsov. All rights reserved.
//

import XCTest
@testable import ResultPromises

private final class URLSessionExtensionTets: XCTestCase {
  
  struct TestReminder: Codable {
    let userId: Int
    let id: Int
    let title: String
    let completed: Bool
  }
  
  let session = URLSession.shared
  
  func testCorrectJSONObjectRetrival() {
    
    let fetchPromise: Promise<[TestReminder]> = session.fetchRESTObject(from: "https://jsonplaceholder.typicode.com/todos")
    
    let exp = expectation(description: "Network request")
    
    fetchPromise
      .onSuccess { (listOfReminders) in
        XCTAssertEqual(listOfReminders.count , 200)
      }
      .onError { (error) in
        switch error {
        // If network error happened - perhaps it means that no connection established
        case NetworkError.network(let embeddedError):
          print("WARKING: Unexpected network error encoutered. It is not indication of failing test yet.\n \(embeddedError?.localizedDescription ?? "<Empty>")")
        default:
          XCTFail("Unexpected exception: \(error.localizedDescription)")
          
        }
      }
      .onComplete { _ in
        exp.fulfill()
    }
    wait(for: [exp], timeout: 5.0)
  }

  func testIncorrectJSONObjectRetrival() {
    let fetchPromise: Promise<[TestReminder]> = session.fetchRESTObject(from: "https://jsonplaceholder.typicode.com/users")
    
    let exp = expectation(description: "Network request")
    
    fetchPromise
      .onSuccess { (listOfReminders) in
        XCTFail("Expectipn expected!")
      }
      .onError { (error) in
        switch error {
        // If network error happened - perhaps it means that no connection established
        case NetworkError.network(let embeddedError):
          print("WARKING: Unexpected network error encoutered. It is not indication of failing test yet.\n \(embeddedError?.localizedDescription ?? "<Empty>")")
        case NetworkError.deserialisation(_):
          // Expected error
          break
        default:
          XCTFail("Unexpected exception: \(error.localizedDescription)")
        }
      }
      .onComplete { _ in
        exp.fulfill()
    }
    wait(for: [exp], timeout: 5.0)
  }

  func testServersideErrorRetrival() {
    let fetchPromise: Promise<[TestReminder]> = session.fetchRESTObject(from: "http://google.co.uk/unexpected_request")
    
    let exp = expectation(description: "Network request")
    
    fetchPromise
      .onSuccess { (listOfReminders) in
        XCTFail("Expectipn expected!")
      }
      .onError { (error) in
        switch error {
        // If network error happened - perhaps it means that no connection established
        case NetworkError.network(let embeddedError):
          print("WARKING: Unexpected network error encoutered. It is not indication of failing test yet.\n \(embeddedError?.localizedDescription ?? "<Empty>")")
        case NetworkError.http(let errorCode):
          XCTAssertEqual(errorCode, 404)
          // Expected error
          break
        default:
          XCTFail("Unexpected exception: \(error.localizedDescription)")
        }
      }
      .onComplete { _ in
        exp.fulfill()
    }
    wait(for: [exp], timeout: 5.0)
  }

  func testAInvalidAddressErrorRetrival() {
    let fetchPromise: Promise<[TestReminder]> = session.fetchRESTObject(from: "Incorect address")
    
    let exp = expectation(description: "Network request")
    
    fetchPromise
      .onSuccess { (listOfReminders) in
        XCTFail("Expectipn expected!")
      }
      .onError { (error) in
        switch error {
        case NetworkError.request:
          // Expected error
          break
        default:
          XCTFail("Unexpected exception: \(error.localizedDescription)")
        }
      }
      .onComplete { _ in
        exp.fulfill()
      }
    wait(for: [exp], timeout: 5.0)
  }

}
